# 作用域

变量作用域，如下例子所示，变量err的作用域问题会导致Func1无法正确的返回err的值

```
package main

import (
	"errors"
	"fmt"
)

func Func1(times int) (err error) {
	for i := 0; i < times; i++ {
		err := errors.New("fakeError1") // 这种写法会导致err实际有两个，因为作用域的问题，外部返回的err会永远是nil
		if err != nil {
			continue
		}
		return nil
	}
	return err
}

func Func2(times int) error {
	var err error
	for i := 0; i < times; i++ {
		err = errors.New("fakeError2")
		if err != nil {
			continue
		}
		return nil
	}
	return err

}

func main() {
	fmt.Println(Func1(2))
	fmt.Println(Func2(2))
	// 运行结果：是Func1的错误被吞掉了
	//	<nil>
	//	fakeError2
}
```
